2019-03-24 22:31:55,941[remote_connection.py line:117] INFO: Could not connect to port 4723 on host 0.0.0.0
2019-03-24 22:31:55,941[remote_connection.py line:136] INFO: Could not get IP address for host: 0.0.0.0
2019-03-24 22:31:55,942[remote_connection.py line:388] DEBUG: POST http://0.0.0.0:4723/wd/hub/session {"desiredCapabilities": {"app": "C:\\Users\\Mir-Z\\Desktop\\my\\App\\kaoyan3.1.0.apk", "automationName": "uiautomator2", "deviceName": "127.0.0.1:62025", "appPackage": "com.tal.kaoyan", "appActivity": "com.tal.kaoyan.ui.activity.SplashActivity", "platformName": "Android", "noReset": true, "platformVersion": "5.1.1"}, "capabilities": {"firstMatch": [{"appium:noReset": true, "appium:platformVersion": "5.1.1", "appium:app": "C:\\Users\\Mir-Z\\Desktop\\my\\App\\kaoyan3.1.0.apk", "platformName": "Android", "appium:appPackage": "com.tal.kaoyan", "appium:deviceName": "127.0.0.1:62025", "appium:appActivity": "com.tal.kaoyan.ui.activity.SplashActivity", "appium:automationName": "uiautomator2"}]}}
2019-03-24 22:31:55,985[connectionpool.py line:205] DEBUG: Starting new HTTP connection (1): 0.0.0.0:4723
2019-03-24 22:31:55,986[retry.py line:400] DEBUG: Incremented Retry for (url='/wd/hub/session'): Retry(total=2, connect=None, read=None, redirect=None, status=None)
2019-03-24 22:31:55,986[connectionpool.py line:662] WARNING: Retrying (Retry(total=2, connect=None, read=None, redirect=None, status=None)) after connection broken by 'NewConnectionError('<urllib3.connection.HTTPConnection object at 0x038F13F0>: Failed to establish a new connection: [WinError 10049] 在其上下文中，该请求的地址无效。',)': /wd/hub/session
2019-03-24 22:31:56,013[connectionpool.py line:205] DEBUG: Starting new HTTP connection (2): 0.0.0.0:4723
2019-03-24 22:31:56,014[retry.py line:400] DEBUG: Incremented Retry for (url='/wd/hub/session'): Retry(total=1, connect=None, read=None, redirect=None, status=None)
2019-03-24 22:31:56,014[connectionpool.py line:662] WARNING: Retrying (Retry(total=1, connect=None, read=None, redirect=None, status=None)) after connection broken by 'NewConnectionError('<urllib3.connection.HTTPConnection object at 0x038F1490>: Failed to establish a new connection: [WinError 10049] 在其上下文中，该请求的地址无效。',)': /wd/hub/session
2019-03-24 22:31:56,015[connectionpool.py line:205] DEBUG: Starting new HTTP connection (3): 0.0.0.0:4723
2019-03-24 22:31:56,015[retry.py line:400] DEBUG: Incremented Retry for (url='/wd/hub/session'): Retry(total=0, connect=None, read=None, redirect=None, status=None)
2019-03-24 22:31:56,015[connectionpool.py line:662] WARNING: Retrying (Retry(total=0, connect=None, read=None, redirect=None, status=None)) after connection broken by 'NewConnectionError('<urllib3.connection.HTTPConnection object at 0x038F1590>: Failed to establish a new connection: [WinError 10049] 在其上下文中，该请求的地址无效。',)': /wd/hub/session
2019-03-24 22:31:56,016[connectionpool.py line:205] DEBUG: Starting new HTTP connection (4): 0.0.0.0:4723
